[2023-08-25T16:09:56.166+0000] {taskinstance.py:1165} INFO - Dependencies all met for <TaskInstance: user_processing.process_user manual__2023-08-25T16:09:54.083272+00:00 [queued]>
[2023-08-25T16:09:56.176+0000] {taskinstance.py:1165} INFO - Dependencies all met for <TaskInstance: user_processing.process_user manual__2023-08-25T16:09:54.083272+00:00 [queued]>
[2023-08-25T16:09:56.176+0000] {taskinstance.py:1362} INFO - 
--------------------------------------------------------------------------------
[2023-08-25T16:09:56.177+0000] {taskinstance.py:1363} INFO - Starting attempt 1 of 1
[2023-08-25T16:09:56.177+0000] {taskinstance.py:1364} INFO - 
--------------------------------------------------------------------------------
[2023-08-25T16:09:56.189+0000] {taskinstance.py:1383} INFO - Executing <Task(PythonOperator): process_user> on 2023-08-25 16:09:54.083272+00:00
[2023-08-25T16:09:56.196+0000] {standard_task_runner.py:55} INFO - Started process 3714 to run task
[2023-08-25T16:09:56.199+0000] {standard_task_runner.py:82} INFO - Running: ['***', 'tasks', 'run', 'user_processing', 'process_user', 'manual__2023-08-25T16:09:54.083272+00:00', '--job-id', '32', '--raw', '--subdir', 'DAGS_FOLDER/user_processing.py', '--cfg-path', '/tmp/tmpx2twmet3']
[2023-08-25T16:09:56.201+0000] {standard_task_runner.py:83} INFO - Job 32: Subtask process_user
[2023-08-25T16:09:56.256+0000] {task_command.py:376} INFO - Running <TaskInstance: user_processing.process_user manual__2023-08-25T16:09:54.083272+00:00 [running]> on host 22e2fb7a3f74
[2023-08-25T16:09:56.316+0000] {taskinstance.py:1592} INFO - Exporting the following env vars:
AIRFLOW_CTX_DAG_OWNER=***
AIRFLOW_CTX_DAG_ID=user_processing
AIRFLOW_CTX_TASK_ID=process_user
AIRFLOW_CTX_EXECUTION_DATE=2023-08-25T16:09:54.083272+00:00
AIRFLOW_CTX_TRY_NUMBER=1
AIRFLOW_CTX_DAG_RUN_ID=manual__2023-08-25T16:09:54.083272+00:00
[2023-08-25T16:09:56.325+0000] {taskinstance.py:1851} ERROR - Task failed with exception
Traceback (most recent call last):
  File "/home/airflow/.local/lib/python3.7/site-packages/airflow/operators/python.py", line 175, in execute
    return_value = self.execute_callable()
  File "/home/airflow/.local/lib/python3.7/site-packages/airflow/operators/python.py", line 193, in execute_callable
    return self.python_callable(*self.op_args, **self.op_kwargs)
  File "/opt/airflow/dags/user_processing.py", line 12, in _process_user
    user = user[0]['results'][0]
KeyError: 0
[2023-08-25T16:09:56.339+0000] {taskinstance.py:1406} INFO - Marking task as FAILED. dag_id=user_processing, task_id=process_user, execution_date=20230825T160954, start_date=20230825T160956, end_date=20230825T160956
[2023-08-25T16:09:56.352+0000] {standard_task_runner.py:105} ERROR - Failed to execute job 32 for task process_user (0; 3714)
[2023-08-25T16:09:56.371+0000] {local_task_job.py:164} INFO - Task exited with return code 1
[2023-08-25T16:09:56.390+0000] {local_task_job.py:273} INFO - 0 downstream tasks scheduled from follow-on schedule check
